<?xml version="1.0" ?>
<!-- =================================================================================== -->
<!-- |    This document was autogenerated by xacro from servera_hw.urdf.xacro          | -->
<!-- |    EDITING THIS FILE BY HAND IS NOT RECOMMENDED                                 | -->
<!-- =================================================================================== -->
<robot name="Servera">
  <!-- reference taken from: https://github.com/linorobot/linorobot2/tree/jazzy -->
  <!-- ====================================================== Wheels ============================================ -->
  <!-- ======================================================  Castor Wheels ============================================ -->
  <!-- Basic Primary Colors -->
  <material name="red">
    <color rgba="1.0 0.0 0.0 1.0"/>
  </material>
  <material name="green">
    <color rgba="0.0 1.0 0.0 1.0"/>
  </material>
  <material name="blue">
    <color rgba="0.0 0.0 1.0 1.0"/>
  </material>
  <material name="white">
    <color rgba="1.0 1.0 1.0 1.0"/>
  </material>
  <material name="black">
    <color rgba="0.0 0.0 0.0 1.0"/>
  </material>
  <material name="grey">
    <color rgba="0.5 0.5 0.5 1.0"/>
  </material>
  <material name="light_grey">
    <color rgba="0.7 0.7 0.7 1.0"/>
  </material>
  <material name="dark_grey">
    <color rgba="0.3 0.3 0.3 1.0"/>
  </material>
  <!-- Secondary Colors -->
  <material name="yellow">
    <color rgba="1.0 1.0 0.0 1.0"/>
  </material>
  <material name="cyan">
    <color rgba="0.0 1.0 1.0 1.0"/>
  </material>
  <material name="magenta">
    <color rgba="1.0 0.0 1.0 1.0"/>
  </material>
  <material name="orange">
    <color rgba="1.0 0.647 0.0 1.0"/>
  </material>
  <material name="purple">
    <color rgba="0.5 0.0 0.5 1.0"/>
  </material>
  <material name="pink">
    <color rgba="1.0 0.753 0.796 1.0"/>
  </material>
  <material name="brown">
    <color rgba="0.647 0.165 0.165 1.0"/>
  </material>
  <!-- Darker Variants -->
  <material name="dark_red">
    <color rgba="0.5 0.0 0.0 1.0"/>
  </material>
  <material name="dark_green">
    <color rgba="0.0 0.5 0.0 1.0"/>
  </material>
  <material name="dark_blue">
    <color rgba="0.0 0.0 0.5 1.0"/>
  </material>
  <!-- Lighter Variants -->
  <material name="light_red">
    <color rgba="1.0 0.5 0.5 1.0"/>
  </material>
  <material name="light_green">
    <color rgba="0.5 1.0 0.5 1.0"/>
  </material>
  <material name="light_blue">
    <color rgba="0.5 0.5 1.0 1.0"/>
  </material>
  <!-- Metallic Materials -->
  <material name="silver">
    <color rgba="0.75 0.75 0.75 1.0"/>
  </material>
  <material name="gold">
    <color rgba="1.0 0.843 0.0 1.0"/>
  </material>
  <ros2_control name="GazeboSystem" type="system">
    <hardware>
      <plugin>mock_components/GenericSystem</plugin>
      <param name="calculate_dynamics">true</param>
      <param name="custom_interface_with_following_offset"/>
      <param name="disable_commands">false</param>
      <param name="mock_gpio_commands">false</param>
      <param name="mock_sensor_commands">false</param>
      <param name="position_state_following_offset">0.0</param>
    </hardware>
    <!-- Left wheel joint -->
    <joint name="left_wheel_joint">
      <command_interface name="velocity"/>
      <state_interface name="position"/>
      <state_interface name="velocity"/>
    </joint>
    <!-- Right wheel joint -->
    <joint name="right_wheel_joint">
      <command_interface name="velocity"/>
      <state_interface name="position"/>
      <state_interface name="velocity"/>
    </joint>
  </ros2_control>
  <!-- lidar definition -->
  <link name="base_footprint"/>
  <link name="base_link">
    <visual>
      <origin rpy="0 0 0" xyz="0 0 0.05500000000000001"/>
      <geometry>
        <box size="0.5 0.3 0.2"/>
      </geometry>
      <material name="yellow">
        <color rgba="0.8784 0.6627 0.6627 1.0"/>
      </material>
    </visual>
    <collision>
      <origin rpy="0 0 0" xyz="0 0 0.05500000000000001"/>
      <geometry>
        <box size="0.5 0.3 0.2"/>
      </geometry>
    </collision>
    <inertial>
      <origin rpy="0 0 0" xyz="0 0 0.05500000000000001"/>
      <mass value="1"/>
      <inertia ixx="0.010833333333333334" ixy="0.0" ixz="0.0" iyy="0.02416666666666667" iyz="0.0" izz="0.02833333333333333"/>
    </inertial>
  </link>
  <gazebo reference="base_link">
    <visual>
      <material>
        <ambient>0.8392 0.6314 0.0 1.0</ambient>
        <diffuse>0.8392 0.6314 0.0 1.0</diffuse>
        <specular>0.99 0.99 0.99 1.0</specular>
        <emissive>0.0 0.0 0.0 0.0</emissive>
      </material>
    </visual>
  </gazebo>
  <joint name="base_to_footprint" type="fixed">
    <parent link="base_footprint"/>
    <child link="base_link"/>
    <origin rpy="0 0 0" xyz="0 0 0.075"/>
  </joint>
  <link name="left_wheel_link">
    <visual>
      <origin rpy="1.5707963267948966 0 0" xyz="0 0 0"/>
      <geometry>
        <cylinder length="0.025" radius="0.045"/>
      </geometry>
      <material name="blue">
        <color rgba="0.1764 0.4588 0.8509 1.0"/>
      </material>
    </visual>
    <collision>
      <origin rpy="1.5707963267948966 0 0" xyz="0 0 0"/>
      <geometry>
        <cylinder length="0.025" radius="0.045"/>
      </geometry>
    </collision>
    <inertial>
      <origin rpy="0 0 0" xyz="0 0 0"/>
      <mass value="0.1"/>
      <inertia ixx="8.100000000000002e-05" ixy="0" ixz="0" iyy="8.100000000000002e-05" iyz="0" izz="8.100000000000002e-05"/>
    </inertial>
  </link>
  <gazebo reference="left_wheel_link">
    <mu1>1.0</mu1>
    <mu2>1.0</mu2>
    <kp>10000000.0</kp>
    <kd>1.0</kd>
    <visual>
      <material>
        <ambient>0.1764 0.4588 0.8509 1.0</ambient>
        <diffuse>0.1764 0.4588 0.8509 1.0</diffuse>
        <specular>0.1764 0.4588 0.8509 1.0</specular>
        <emissive>0.0 0.0 0.0 0.0</emissive>
      </material>
    </visual>
  </gazebo>
  <joint name="left_wheel_joint" type="continuous">
    <axis xyz="0 1 0"/>
    <parent link="base_link"/>
    <child link="left_wheel_link"/>
    <origin rpy="0 0 0" xyz="0.03 0.165 -0.03"/>
  </joint>
  <link name="right_wheel_link">
    <visual>
      <origin rpy="1.5707963267948966 0 0" xyz="0 0 0"/>
      <geometry>
        <cylinder length="0.025" radius="0.045"/>
      </geometry>
      <material name="blue">
        <color rgba="0.1764 0.4588 0.8509 1.0"/>
      </material>
    </visual>
    <collision>
      <origin rpy="1.5707963267948966 0 0" xyz="0 0 0"/>
      <geometry>
        <cylinder length="0.025" radius="0.045"/>
      </geometry>
    </collision>
    <inertial>
      <origin rpy="0 0 0" xyz="0 0 0"/>
      <mass value="0.1"/>
      <inertia ixx="8.100000000000002e-05" ixy="0" ixz="0" iyy="8.100000000000002e-05" iyz="0" izz="8.100000000000002e-05"/>
    </inertial>
  </link>
  <gazebo reference="right_wheel_link">
    <mu1>1.0</mu1>
    <mu2>1.0</mu2>
    <kp>10000000.0</kp>
    <kd>1.0</kd>
    <visual>
      <material>
        <ambient>0.1764 0.4588 0.8509 1.0</ambient>
        <diffuse>0.1764 0.4588 0.8509 1.0</diffuse>
        <specular>0.1764 0.4588 0.8509 1.0</specular>
        <emissive>0.0 0.0 0.0 0.0</emissive>
      </material>
    </visual>
  </gazebo>
  <joint name="right_wheel_joint" type="continuous">
    <axis xyz="0 1 0"/>
    <parent link="base_link"/>
    <child link="right_wheel_link"/>
    <origin rpy="0 0 0" xyz="0.03 -0.165 -0.03"/>
  </joint>
  <link name="lidar_link">
    <visual>
      <origin rpy="0 0 0" xyz="0 0 -0.025"/>
      <geometry>
        <cylinder length="0.05" radius="0.0375"/>
      </geometry>
      <material name="green">
        <color rgba="0.003 0.639 0.223 1.0"/>
      </material>
    </visual>
    <collision>
      <origin rpy="0 0 0" xyz="0 0 -0.025"/>
      <geometry>
        <cylinder length="0.05" radius="0.0375"/>
      </geometry>
    </collision>
    <inertial>
      <origin rpy="0 0 0" xyz="0 0 0"/>
      <mass value="0.1"/>
      <inertia ixx="5.598958333333333e-05" ixy="0" ixz="0" iyy="5.598958333333333e-05" iyz="0" izz="7.03125e-05"/>
    </inertial>
  </link>
  <joint name="lidar_link_to_base_link" type="fixed">
    <parent link="base_link"/>
    <child link="lidar_link"/>
    <origin rpy="0 0 0" xyz="0.0 0.0 0.2"/>
  </joint>
  <!-- ADD "base_length" IN THE 'params' LIST, IF YOU WANT TO UNCOMMENT THE FOLLOWING 
    (N.B: this snippet is taken from linorobot2, and is not reuired in servera) -->
  <link name="right_caster_wheel_link">
    <visual>
      <origin rpy="0 0 0" xyz="0 0 0"/>
      <geometry>
        <sphere radius="0.0375"/>
      </geometry>
      <material name="black">
        <color rgba="0.0 0.0 0.0 1.0"/>
      </material>
    </visual>
    <collision>
      <origin rpy="0 0 0" xyz="0 0 0"/>
      <geometry>
        <sphere radius="0.0375"/>
      </geometry>
    </collision>
    <inertial>
      <origin rpy="0 0 0" xyz="0 0 0"/>
      <mass value="0.01"/>
      <inertia ixx="5.6249999999999995e-06" ixy="0" ixz="0" iyy="5.6249999999999995e-06" iyz="0" izz="5.6249999999999995e-06"/>
    </inertial>
  </link>
  <gazebo reference="right_caster_wheel_link">
    <mu1>0.01</mu1>
    <mu2>0.01</mu2>
  </gazebo>
  <joint name="right_caster_wheel_joint" type="fixed">
    <parent link="base_link"/>
    <child link="right_caster_wheel_link"/>
    <origin rpy="0 0 0" xyz=" -0.2125 -0.11249999999999999 -0.0375"/>
  </joint>
  <!-- ADD "base_length" IN THE 'params' LIST, IF YOU WANT TO UNCOMMENT THE FOLLOWING 
    (N.B: this snippet is taken from linorobot2, and is not reuired in servera) -->
  <link name="left_caster_wheel_link">
    <visual>
      <origin rpy="0 0 0" xyz="0 0 0"/>
      <geometry>
        <sphere radius="0.0375"/>
      </geometry>
      <material name="black">
        <color rgba="0.0 0.0 0.0 1.0"/>
      </material>
    </visual>
    <collision>
      <origin rpy="0 0 0" xyz="0 0 0"/>
      <geometry>
        <sphere radius="0.0375"/>
      </geometry>
    </collision>
    <inertial>
      <origin rpy="0 0 0" xyz="0 0 0"/>
      <mass value="0.01"/>
      <inertia ixx="5.6249999999999995e-06" ixy="0" ixz="0" iyy="5.6249999999999995e-06" iyz="0" izz="5.6249999999999995e-06"/>
    </inertial>
  </link>
  <gazebo reference="left_caster_wheel_link">
    <mu1>0.01</mu1>
    <mu2>0.01</mu2>
  </gazebo>
  <joint name="left_caster_wheel_joint" type="fixed">
    <parent link="base_link"/>
    <child link="left_caster_wheel_link"/>
    <origin rpy="0 0 0" xyz=" -0.2125 0.11249999999999999 -0.0375"/>
  </joint>
</robot>
